ERROR 2023-05-13 18:58:37,213 log 14068 4572 Internal Server Error: /group/CreateGroup/
Traceback (most recent call last):
  File "C:\Users\Acer\AppData\Local\Programs\Python\Python311\Lib\site-packages\django\utils\datastructures.py", line 84, in __getitem__
    list_ = super().__getitem__(key)
            ^^^^^^^^^^^^^^^^^^^^^^^^
KeyError: 'emails'

During handling of the above exception, another exception occurred:

Traceback (most recent call last):
  File "C:\Users\Acer\AppData\Local\Programs\Python\Python311\Lib\site-packages\django\core\handlers\exception.py", line 56, in inner
    response = get_response(request)
               ^^^^^^^^^^^^^^^^^^^^^
  File "C:\Users\Acer\AppData\Local\Programs\Python\Python311\Lib\site-packages\django\core\handlers\base.py", line 197, in _get_response
    response = wrapped_callback(request, *callback_args, **callback_kwargs)
               ^^^^^^^^^^^^^^^^^^^^^^^^^^^^^^^^^^^^^^^^^^^^^^^^^^^^^^^^^^^^
  File "C:\Users\Acer\AppData\Local\Programs\Python\Python311\Lib\site-packages\django\views\decorators\csrf.py", line 55, in wrapped_view
    return view_func(*args, **kwargs)
           ^^^^^^^^^^^^^^^^^^^^^^^^^^
  File "C:\Users\Acer\AppData\Local\Programs\Python\Python311\Lib\site-packages\django\views\generic\base.py", line 103, in view
    return self.dispatch(request, *args, **kwargs)
           ^^^^^^^^^^^^^^^^^^^^^^^^^^^^^^^^^^^^^^^
  File "C:\Users\Acer\AppData\Local\Programs\Python\Python311\Lib\site-packages\rest_framework\views.py", line 509, in dispatch
    response = self.handle_exception(exc)
               ^^^^^^^^^^^^^^^^^^^^^^^^^^
  File "C:\Users\Acer\AppData\Local\Programs\Python\Python311\Lib\site-packages\rest_framework\views.py", line 469, in handle_exception
    self.raise_uncaught_exception(exc)
  File "C:\Users\Acer\AppData\Local\Programs\Python\Python311\Lib\site-packages\rest_framework\views.py", line 480, in raise_uncaught_exception
    raise exc
  File "C:\Users\Acer\AppData\Local\Programs\Python\Python311\Lib\site-packages\rest_framework\views.py", line 506, in dispatch
    response = handler(request, *args, **kwargs)
               ^^^^^^^^^^^^^^^^^^^^^^^^^^^^^^^^^
  File "E:\uni\8\OOD\Enigma_BackEnd\Enigma\Group\views.py", line 24, in post
    data["emails"] = request.data['emails']
                     ~~~~~~~~~~~~^^^^^^^^^^
  File "C:\Users\Acer\AppData\Local\Programs\Python\Python311\Lib\site-packages\django\utils\datastructures.py", line 86, in __getitem__
    raise MultiValueDictKeyError(key)
django.utils.datastructures.MultiValueDictKeyError: 'emails'
ERROR 2023-05-13 18:58:37,216 basehttp 14068 4572 "POST /group/CreateGroup/ HTTP/1.1" 500 106419
ERROR 2023-05-13 18:59:26,194 log 14068 4572 Internal Server Error: /group/CreateGroup/
Traceback (most recent call last):
  File "C:\Users\Acer\AppData\Local\Programs\Python\Python311\Lib\site-packages\django\core\handlers\exception.py", line 56, in inner
    response = get_response(request)
               ^^^^^^^^^^^^^^^^^^^^^
  File "C:\Users\Acer\AppData\Local\Programs\Python\Python311\Lib\site-packages\django\core\handlers\base.py", line 197, in _get_response
    response = wrapped_callback(request, *callback_args, **callback_kwargs)
               ^^^^^^^^^^^^^^^^^^^^^^^^^^^^^^^^^^^^^^^^^^^^^^^^^^^^^^^^^^^^
  File "C:\Users\Acer\AppData\Local\Programs\Python\Python311\Lib\site-packages\django\views\decorators\csrf.py", line 55, in wrapped_view
    return view_func(*args, **kwargs)
           ^^^^^^^^^^^^^^^^^^^^^^^^^^
  File "C:\Users\Acer\AppData\Local\Programs\Python\Python311\Lib\site-packages\django\views\generic\base.py", line 103, in view
    return self.dispatch(request, *args, **kwargs)
           ^^^^^^^^^^^^^^^^^^^^^^^^^^^^^^^^^^^^^^^
  File "C:\Users\Acer\AppData\Local\Programs\Python\Python311\Lib\site-packages\rest_framework\views.py", line 509, in dispatch
    response = self.handle_exception(exc)
               ^^^^^^^^^^^^^^^^^^^^^^^^^^
  File "C:\Users\Acer\AppData\Local\Programs\Python\Python311\Lib\site-packages\rest_framework\views.py", line 469, in handle_exception
    self.raise_uncaught_exception(exc)
  File "C:\Users\Acer\AppData\Local\Programs\Python\Python311\Lib\site-packages\rest_framework\views.py", line 480, in raise_uncaught_exception
    raise exc
  File "C:\Users\Acer\AppData\Local\Programs\Python\Python311\Lib\site-packages\rest_framework\views.py", line 506, in dispatch
    response = handler(request, *args, **kwargs)
               ^^^^^^^^^^^^^^^^^^^^^^^^^^^^^^^^^
  File "E:\uni\8\OOD\Enigma_BackEnd\Enigma\Group\views.py", line 25, in post
    data["emails"].append(str(self.request.user.email))
    ^^^^^^^^^^^^^^^^^^^^^
AttributeError: 'str' object has no attribute 'append'
ERROR 2023-05-13 18:59:26,195 basehttp 14068 4572 "POST /group/CreateGroup/ HTTP/1.1" 500 98367
ERROR 2023-05-13 18:59:32,256 log 14068 4572 Internal Server Error: /group/CreateGroup/
Traceback (most recent call last):
  File "C:\Users\Acer\AppData\Local\Programs\Python\Python311\Lib\site-packages\django\core\handlers\exception.py", line 56, in inner
    response = get_response(request)
               ^^^^^^^^^^^^^^^^^^^^^
  File "C:\Users\Acer\AppData\Local\Programs\Python\Python311\Lib\site-packages\django\core\handlers\base.py", line 197, in _get_response
    response = wrapped_callback(request, *callback_args, **callback_kwargs)
               ^^^^^^^^^^^^^^^^^^^^^^^^^^^^^^^^^^^^^^^^^^^^^^^^^^^^^^^^^^^^
  File "C:\Users\Acer\AppData\Local\Programs\Python\Python311\Lib\site-packages\django\views\decorators\csrf.py", line 55, in wrapped_view
    return view_func(*args, **kwargs)
           ^^^^^^^^^^^^^^^^^^^^^^^^^^
  File "C:\Users\Acer\AppData\Local\Programs\Python\Python311\Lib\site-packages\django\views\generic\base.py", line 103, in view
    return self.dispatch(request, *args, **kwargs)
           ^^^^^^^^^^^^^^^^^^^^^^^^^^^^^^^^^^^^^^^
  File "C:\Users\Acer\AppData\Local\Programs\Python\Python311\Lib\site-packages\rest_framework\views.py", line 509, in dispatch
    response = self.handle_exception(exc)
               ^^^^^^^^^^^^^^^^^^^^^^^^^^
  File "C:\Users\Acer\AppData\Local\Programs\Python\Python311\Lib\site-packages\rest_framework\views.py", line 469, in handle_exception
    self.raise_uncaught_exception(exc)
  File "C:\Users\Acer\AppData\Local\Programs\Python\Python311\Lib\site-packages\rest_framework\views.py", line 480, in raise_uncaught_exception
    raise exc
  File "C:\Users\Acer\AppData\Local\Programs\Python\Python311\Lib\site-packages\rest_framework\views.py", line 506, in dispatch
    response = handler(request, *args, **kwargs)
               ^^^^^^^^^^^^^^^^^^^^^^^^^^^^^^^^^
  File "E:\uni\8\OOD\Enigma_BackEnd\Enigma\Group\views.py", line 25, in post
    data["emails"].append(str(self.request.user.email))
    ^^^^^^^^^^^^^^^^^^^^^
AttributeError: 'str' object has no attribute 'append'
ERROR 2023-05-13 18:59:32,258 basehttp 14068 4572 "POST /group/CreateGroup/ HTTP/1.1" 500 98402
ERROR 2023-05-13 18:59:36,911 log 14068 4572 Internal Server Error: /group/CreateGroup/
Traceback (most recent call last):
  File "C:\Users\Acer\AppData\Local\Programs\Python\Python311\Lib\site-packages\django\core\handlers\exception.py", line 56, in inner
    response = get_response(request)
               ^^^^^^^^^^^^^^^^^^^^^
  File "C:\Users\Acer\AppData\Local\Programs\Python\Python311\Lib\site-packages\django\core\handlers\base.py", line 197, in _get_response
    response = wrapped_callback(request, *callback_args, **callback_kwargs)
               ^^^^^^^^^^^^^^^^^^^^^^^^^^^^^^^^^^^^^^^^^^^^^^^^^^^^^^^^^^^^
  File "C:\Users\Acer\AppData\Local\Programs\Python\Python311\Lib\site-packages\django\views\decorators\csrf.py", line 55, in wrapped_view
    return view_func(*args, **kwargs)
           ^^^^^^^^^^^^^^^^^^^^^^^^^^
  File "C:\Users\Acer\AppData\Local\Programs\Python\Python311\Lib\site-packages\django\views\generic\base.py", line 103, in view
    return self.dispatch(request, *args, **kwargs)
           ^^^^^^^^^^^^^^^^^^^^^^^^^^^^^^^^^^^^^^^
  File "C:\Users\Acer\AppData\Local\Programs\Python\Python311\Lib\site-packages\rest_framework\views.py", line 509, in dispatch
    response = self.handle_exception(exc)
               ^^^^^^^^^^^^^^^^^^^^^^^^^^
  File "C:\Users\Acer\AppData\Local\Programs\Python\Python311\Lib\site-packages\rest_framework\views.py", line 469, in handle_exception
    self.raise_uncaught_exception(exc)
  File "C:\Users\Acer\AppData\Local\Programs\Python\Python311\Lib\site-packages\rest_framework\views.py", line 480, in raise_uncaught_exception
    raise exc
  File "C:\Users\Acer\AppData\Local\Programs\Python\Python311\Lib\site-packages\rest_framework\views.py", line 506, in dispatch
    response = handler(request, *args, **kwargs)
               ^^^^^^^^^^^^^^^^^^^^^^^^^^^^^^^^^
  File "E:\uni\8\OOD\Enigma_BackEnd\Enigma\Group\views.py", line 25, in post
    data["emails"].append(str(self.request.user.email))
    ^^^^^^^^^^^^^^^^^^^^^
AttributeError: 'str' object has no attribute 'append'
ERROR 2023-05-13 18:59:36,912 basehttp 14068 4572 "POST /group/CreateGroup/ HTTP/1.1" 500 98375
ERROR 2023-05-14 00:31:51,576 log 2652 14600 Internal Server Error: /group/GroupInfo/
ERROR 2023-05-14 00:31:51,578 log 2652 14600 Internal Server Error: /group/GroupInfo/
ERROR 2023-05-14 00:31:51,592 log 2652 14600 Internal Server Error: /group/ShowGroups/
ERROR 2023-05-14 00:31:51,608 log 2652 14600 Internal Server Error: /group/ShowMembers/
ERROR 2023-05-14 00:32:52,318 log 13468 2160 Internal Server Error: /group/GroupInfo/
ERROR 2023-05-14 00:32:52,321 log 13468 2160 Internal Server Error: /group/GroupInfo/
ERROR 2023-05-14 00:32:52,334 log 13468 2160 Internal Server Error: /group/ShowGroups/
ERROR 2023-05-14 00:32:52,353 log 13468 2160 Internal Server Error: /group/ShowMembers/
